<?xml version="1.0"?>

<robot name="diff_drive_robot">

  <!-- Ground reference frame -->
  <link name="base_footprint"/>


  <!-- Robot chassis -->
  <link name="base_link">

    <visual>
      <geometry>
        <box size="0.40 0.30 0.10"/>
      </geometry>

      <origin xyz="0 0 0.05"/>

      <material name="blue">
        <color rgba="0.2 0.4 1.0 1.0"/>
      </material>

    </visual>


    <collision>
      <geometry>
        <box size="0.40 0.30 0.10"/>
      </geometry>

      <origin xyz="0 0 0.05"/>
    </collision>


  </link>


  <!-- base_footprint to base_link -->
  <joint name="base_joint" type="fixed">

    <parent link="base_footprint"/>
    <child link="base_link"/>

    <origin xyz="0 0 0"/>

  </joint>



  <!-- Left wheel -->
  <link name="left_wheel">

    <visual>

      <geometry>
        <cylinder radius="0.05" length="0.03"/>
      </geometry>

      <origin rpy="1.5708 0 0"/>

      <material name="black">
        <color rgba="0.05 0.05 0.05 1.0"/>
      </material>

    </visual>

  </link>



  <!-- Right wheel -->
  <link name="right_wheel">

    <visual>

      <geometry>
        <cylinder radius="0.05" length="0.03"/>
      </geometry>

      <origin rpy="1.5708 0 0"/>

      <material name="black">
        <color rgba="0.05 0.05 0.05 1.0"/>
      </material>

    </visual>

  </link>



  <!-- Left wheel joint -->
  <joint name="left_wheel_joint" type="continuous">

    <parent link="base_link"/>
    <child link="left_wheel"/>

    <origin xyz="0 0.18 0.05"/>

    <axis xyz="0 1 0"/>

  </joint>



  <!-- Right wheel joint -->
  <joint name="right_wheel_joint" type="continuous">

    <parent link="base_link"/>
    <child link="right_wheel"/>

    <origin xyz="0 -0.18 0.05"/>

    <axis xyz="0 1 0"/>

  </joint>


</robot>
